Workbook

Sheet 调拨单汇总表
A1: 货件信息 | L1: 询价记录 | AC1: 物流信息 | AG1: 积加录入 | AM1: 辅助 | AO1: 货件跟踪 | AV1: 货件跟踪详情
A2: 调拨需求名称 | B2: 货件名称 或 箱唛名称 | C2: 站点 | D2: 调出仓库 | E2: 调入仓库 | F2: 货运方式 | G2: 发货数量 | H2: 箱数 | I2: 货件编号 | J2: 配送地址（仓库） | K2: 仓库邮编 | L2: 询价需求发起人 | M2: 提货状态 | N2: 实重 | O2: 泡重 | P2: 立方 | Q2: 艾特询价执行人 | R2: 询价状态 询价需求人填写 | S2: 询价日期 询价执行人填写 | T2: 通知制单人 询价执行人填写 | U2: 注意事项 询价需求人、询价执行人填写 | V2: 询价前单价 | W2: 询价后单价 | X2: 单价减免 | Y2: 预估计费重 | Z2: 总价减免 | AA2: 提货信息 | AB2: 是否发给经理优惠备注 | AC2: 实际出库日期 | AD2: 物流商 | AE2: 物流方式（名称同物流价卡） | AF2: 物流追踪号 | AG2: 预计送达日期 | AH2: 物流方式（名称同积加） | AI2: 预估费用 | AJ2: 备注（预估费用明细） | AK2: 录入情况 | AL2: 制单文件 | AM2: 货件编号 | AN2: 物流追踪号 | AO2: 登记地址 | AP2: 实际签收时间 | AQ2: 时效(天) | AR2: 后台货件状态 | AS2: 接收数量 | AT2: 接收差异 | AU2: 索赔进度 | AV2: 离港时间 | AW2: 到港时间 | AX2: 到仓时间 | AY2: 转运时间 | AZ2: 签收时间 | BA2: 查验时间 | BB2: 查验放行时间 | BC2: POD | BD2: 异常处理记录

Sheet 询价详情记录总
A1: 询价日期 | B1: 站点 | C1: 货运方式 | D1: 仓库 | E1: 箱数 | F1: 实重 | G1: 泡重 | H1: 预估计费重 | I1: 立方 | J1: 邮编 | K1: 是否偏远仓 | L1: 物流商 | M1: 物流方式（名称同物流价卡） | N1: 时效 | O1: 备注 | P1: 询价格式 | Q1: 截图（方便后续对账） | R1: 询价前单价 | S1: 询价前总价 | T1: 询价后单价 | U1: 询价后总价 | V1: 单价减免 | W1: 总价减免
A2: 45281 | B2: US | C2: 海运 | D2: IND9 | E2: 7 | F2: 131.7 | G2: 110.76 | H2: 132 | I2: 0.65 | J2: 46143 | K2: 否 | L2: 德速 | M2: 美森限时达-正班 | O2: 不够150kg+2/kg | P2: IND9：7箱-132KG-0.65方 | R2: 17.66 | S2: 2331.12 | T2: 17.66 | U2: 0 | V2: -17.66 | W2: -2331.12

Sheet FBA地址记录
A1: 收货地址 | B1: 偏远情况 | C1: 邮编 | E1: 是否偏远仓查询网址：https://ziplucas.com/
A2: ABE3 | B2: 否 | C2: 18031-1536
A3: ABE8 | B3: 否 | C3: 08518-2200
A4: AVP1 | B4: 否 | C4: 18202-9361
A5: CAE1 | B5: 否 | C5: 29172
A6: CLT2 | B6: 否 | C6: 28214-8082
A7: FTW1 | B7: 否 | C7: 75241-7203
A8: FTW3 | B8: 否 | C8: 76177-2517
A9: FTW9 | B9: 否 | C9: 75019-3989
A10: FWA4 | B10: 否 | C10: 46809-9771
A11: GYR2 | B11: 否 | C11: 85395-7672
A12: GYR3 | B12: 否 | C12: 85043-2356
A13: IND4 | B13: UPS偏远 | C13: 46231-1132
A14: IND9 | B14: 否 | C14: 46143
A15: LAS1 | B15: UPS/FEDEX偏远 | C15: 89044
A16: LAX9 | B16: 否 | C16: 92337-7441
A17: MDT2 | B17: UPS/FEDEX偏远 | C17: 21901-2914
A18: MDW2 | B18: 否 | C18: 60433-3280
A19: MEM1 | B19: 否 | C19: 38118
A20: MGE1 | B20: 否 | C20: 30517-3002
A21: MQJ1 | B21: 否 | C21: 46140
A22: ONT2 | B22: 否 | C22: 92408-0123
A23: ONT8 | B23: 否 | C23: 92551-9534
A24: ORF2 | B24: 否 | C24: 23321-1425
A25: SCK4 | B25: UPS/FEDEX偏远 | C25: 95215
A26: SDF8 | B26: 否 | C26: 47130
A27: SMF3 | B27: 否 | C27: 95206-8202
A28: TEB9 | B28: 否 | C28: 08873
A29: WRO5 | B29: 否 | C29: 06126
A30: YYZ7 | B30: 否 | C30: L7E 4L8
A31: YYC1 | B31: 否 | C31: T4A 1C6
A32: YEG2 | B32: 否 | C32: T7X 2X2
A33: YVR4 | B33: 否 | C33: V4M 0B9
A34: HAJ1 | B34: 否 | C34: 38350
A35: BHX4 | B35: 否 | C35: CV5 9PF
A36: DTM2 | B36: 否 | C36: 44145
A37: SWF2 | B37: UPS/FEDEX偏远 | C37: 12533-6159
A38: TY02 | B38: 否 | C38: 346-8511
A39: NRT5 | B39: 否 | C39: 350-1182
A40: FSZ1 | B40: 否 | C40: 250-8560
...

Sheet 每周更新
A1: 提货状态 | B1: (全部)
A2: 询价状态 询价需求人填写 | B2: (全部)
A4: 站点 | B4: 货运方式 | C4: 配送地址（仓库） | D4: 求和项:箱数 | E4: 求和项:实重 | F4: 求和项:泡重 | G4: 求和项:立方
A5: (空白) | B5: (空白) | C5: (空白)
A6: US | B6: 海运 | C6: IND9 | D6: 7 | E6: 131.7 | F6: 110.76 | G6: 0.65
A7: 总计 | D7: 7 | E7: 131.7 | F7: 110.76 | G7: 0.65
C58: 询价之前 筛选 未提货未询价部分的【注意事项】， 查看是否有需要注意的 如：指定发xxx渠道/发xxx货代等 | M58: 空运渠道，若有分泡，且泡重>实重，则计费重=实重*50%+泡重*50% 空运渠道有分泡如下： 美通：美国、欧洲、英国 速十：美国 原飞航：美国
A60: 询价日期 | B60: 站点 | C60: 货运方式 | D60: 仓库 | E60: 箱数 | F60: 实重 | G60: 泡重 | H60: 预估计费重 | I60: 立方 | J60: 邮编 | K60: 是否偏远仓 | L60: 物流商 | M60: 物流方式（名称同物流价卡） | N60: 时效 | O60: 备注 | P60: 询价格式 | Q60: 截图（方便后续对账） | R60: 询价前单价 | S60: 询价前总价 | T60: 询价后单价 | U60: 询价后总价 | V60: 单价减免 | W60: 总价减免
A61: 45173 | B61: DE | C61: 空运 | D61: HAJ1 | E61: {=INDEX($D:$D,MATCH(1,($B:$B=C61)*($C:$C=D61),0))} -> #N/A | F61: {=INDEX($E:$E,MATCH(1,($B:$B=C61)*($C:$C=D61),0))} -> #N/A | G61: {=INDEX($F:$F,MATCH(1,($B:$B=C61)*($C:$C=D61),0))} -> #N/A | H61: =IF(MAX(F61:G61)=0,0,IF(MAX(F61:G61)<21,21,IF(F61>G61,ROUNDUP(F61,0),IFERROR(_xlfn.IFS(B61&C61&L61="US空运速十",ROUNDUP((F61+G61)*0.5,0),B61&C61&L61="US空运原飞航",ROUNDUP((F61+G61)*0.5,0),B61&C61&L61="US空运美通",ROUNDUP((F61+G61)*0.5,0),B61&C61&L61="UK空运美通",ROUNDUP((F61+G61)*0.5,0),B61&C61&L617="DE空运美通",ROUNDUP((F61+G61)*0.5,0)),ROUNDUP(MAX(F61:G61),0))))) -> #N/A | I61: {=INDEX($G:$G,MATCH(1,($B:$B=C61)*($C:$C=D61),0))} -> #N/A | J61: =VLOOKUP(D61,FBA地址记录!A:C,3,0) -> 38350 | K61: =IFERROR(VLOOKUP(D61,FBA地址记录!A:B,2,0),"否") -> 否 | L61: 美通 | M61: 欧洲空派A-VAT | N61: 6-10个自然日提取 | P61: =D61&"："&E61&"箱-"&H61&"KG-"&I61&"方" -> #N/A | Q61: =_xlfn.DISPIMG("ID_692C50B4E46442008EF80AB648A9034E",1) -> =DISPIMG("ID_692C50B4E46442008EF80AB648A9034E",1) | R61: 29.5 | S61: =R61*H61 -> #N/A | T61: 28.5 | U61: =T61*H61 -> #N/A | V61: =T61-R61 -> -1 | W61: =U61-S61 -> #N/A
A62: 45173 | B62: UK | C62: 空运 | D62: BHX4 | E62: {=INDEX($D:$D,MATCH(1,($B:$B=C62)*($C:$C=D62),0))} -> #N/A | F62: {=INDEX($E:$E,MATCH(1,($B:$B=C62)*($C:$C=D62),0))} -> #N/A | G62: {=INDEX($F:$F,MATCH(1,($B:$B=C62)*($C:$C=D62),0))} -> #N/A | H62: =IF(MAX(F62:G62)=0,0,IF(MAX(F62:G62)<21,21,IF(F62>G62,ROUNDUP(F62,0),IFERROR(_xlfn.IFS(B62&C62&L62="US空运速十",ROUNDUP((F62+G62)*0.5,0),B62&C62&L62="US空运原飞航",ROUNDUP((F62+G62)*0.5,0),B62&C62&L62="US空运美通",ROUNDUP((F62+G62)*0.5,0),B62&C62&L62="UK空运美通",ROUNDUP((F62+G62)*0.5,0),B62&C62&L618="DE空运美通",ROUNDUP((F62+G62)*0.5,0)),ROUNDUP(MAX(F62:G62),0))))) -> #N/A | I62: {=INDEX($G:$G,MATCH(1,($B:$B=C62)*($C:$C=D62),0))} -> #N/A | J62: =VLOOKUP(D62,FBA地址记录!A:C,3,0) -> CV5 9PF | K62: =IFERROR(VLOOKUP(D62,FBA地址记录!A:B,2,0),"否") -> 否 | L62: 美通 | M62: 英国空派G-VAT递延 | N62: 7-10个自然日提取，DPD派送1-2个工作日 | P62: =D62&"："&E62&"箱-"&H62&"KG-"&I62&"方" -> #N/A | Q62: =_xlfn.DISPIMG("ID_8EFBFD5AA2714E2EBDD28742C52E64E7",1) -> =DISPIMG("ID_8EFBFD5AA2714E2EBDD28742C52E64E7",1) | R62: 27.5 | S62: =R62*H62 -> #N/A | T62: 27 | U62: =T62*H62 -> #N/A | V62: =T62-R62 -> -0.5 | W62: =U62-S62 -> #N/A
A64: 45385 | B64: DE | C64: 空运 | D64: WRO5 | E64: {=INDEX($D:$D,MATCH(1,($B:$B=C64)*($C:$C=D64),0))} -> #N/A | F64: {=INDEX($E:$E,MATCH(1,($B:$B=C64)*($C:$C=D64),0))} -> #N/A | G64: {=INDEX($F:$F,MATCH(1,($B:$B=C64)*($C:$C=D64),0))} -> #N/A | H64: =IF(MAX(F64:G64)=0,0,IF(MAX(F64:G64)<21,21,IF(F64>G64,ROUNDUP(F64,0),IFERROR(_xlfn.IFS(B64&C64&L64="US空运速十",ROUNDUP((F64+G64)*0.5,0),B64&C64&L64="US空运原飞航",ROUNDUP((F64+G64)*0.5,0),B64&C64&L64="US空运美通",ROUNDUP((F64+G64)*0.5,0),B64&C64&L64="UK空运美通",ROUNDUP((F64+G64)*0.5,0),B64&C64&L620="DE空运美通",ROUNDUP((F64+G64)*0.5,0)),ROUNDUP(MAX(F64:G64),0))))) -> #N/A | I64: {=INDEX($G:$G,MATCH(1,($B:$B=C64)*($C:$C=D64),0))} -> #N/A | J64: =VLOOKUP(D64,FBA地址记录!A:C,3,0) -> 06126 | K64: =IFERROR(VLOOKUP(D64,FBA地址记录!A:B,2,0),"否") -> 否 | L64: 美通 | M64: 欧洲空派A-VAT | P64: =D64&"："&E64&"箱-"&H64&"KG-"&I64&"方" -> #N/A | Q64: =_xlfn.DISPIMG("ID_E93BAD842192408F9772E39790901A56",1) -> =DISPIMG("ID_E93BAD842192408F9772E39790901A56",1) | R64: 48 | S64: =R64*H64 -> #N/A | T64: =R64-0.5 -> 47.5 | U64: =T64*H64 -> #N/A | V64: =T64-R64 -> -0.5 | W64: =U64-S64 -> #N/A
A65: 45385 | B65: UK | C65: 空运 | D65: BHX4 | E65: {=INDEX($D:$D,MATCH(1,($B:$B=C65)*($C:$C=D65),0))} -> #N/A | F65: {=INDEX($E:$E,MATCH(1,($B:$B=C65)*($C:$C=D65),0))} -> #N/A | G65: {=INDEX($F:$F,MATCH(1,($B:$B=C65)*($C:$C=D65),0))} -> #N/A | H65: =IF(MAX(F65:G65)=0,0,IF(MAX(F65:G65)<21,21,IF(F65>G65,ROUNDUP(F65,0),IFERROR(_xlfn.IFS(B65&C65&L65="US空运速十",ROUNDUP((F65+G65)*0.5,0),B65&C65&L65="US空运原飞航",ROUNDUP((F65+G65)*0.5,0),B65&C65&L65="US空运美通",ROUNDUP((F65+G65)*0.5,0),B65&C65&L65="UK空运美通",ROUNDUP((F65+G65)*0.5,0),B65&C65&L621="DE空运美通",ROUNDUP((F65+G65)*0.5,0)),ROUNDUP(MAX(F65:G65),0))))) -> #N/A | I65: {=INDEX($G:$G,MATCH(1,($B:$B=C65)*($C:$C=D65),0))} -> #N/A | J65: =VLOOKUP(D65,FBA地址记录!A:C,3,0) -> CV5 9PF | K65: =IFERROR(VLOOKUP(D65,FBA地址记录!A:B,2,0),"否") -> 否 | L65: 美通 | M65: 英国空派G-VAT递延 | P65: =D65&"："&E65&"箱-"&H65&"KG-"&I65&"方" -> #N/A | Q65: =_xlfn.DISPIMG("ID_DB9D8FBEF2BE445EA9E87677451C23FF",1) -> =DISPIMG("ID_DB9D8FBEF2BE445EA9E87677451C23FF",1) | R65: 41.5 | S65: =R65*H65 -> #N/A | T65: =R65-0.5 -> 41 | U65: =T65*H65 -> #N/A | V65: =T65-R65 -> -0.5 | W65: =U65-S65 -> #N/A
W66: =U66-S66 -> 0
A67: 45385 | B67: DE | C67: 空运 | D67: WRO5 | E67: {=INDEX($D:$D,MATCH(1,($B:$B=C67)*($C:$C=D67),0))} -> #N/A | F67: {=INDEX($E:$E,MATCH(1,($B:$B=C67)*($C:$C=D67),0))} -> #N/A | G67: {=INDEX($F:$F,MATCH(1,($B:$B=C67)*($C:$C=D67),0))} -> #N/A | H67: =IF(MAX(F67:G67)=0,0,IF(MAX(F67:G67)<21,21,IF(F67>G67,ROUNDUP(F67,0),IFERROR(_xlfn.IFS(B67&C67&L67="US空运速十",ROUNDUP((F67+G67)*0.5,0),B67&C67&L67="US空运原飞航",ROUNDUP((F67+G67)*0.5,0),B67&C67&L67="US空运美通",ROUNDUP((F67+G67)*0.5,0),B67&C67&L67="UK空运美通",ROUNDUP((F67+G67)*0.5,0),B67&C67&L623="DE空运美通",ROUNDUP((F67+G67)*0.5,0)),ROUNDUP(MAX(F67:G67),0))))) -> #N/A | I67: {=INDEX($G:$G,MATCH(1,($B:$B=C67)*($C:$C=D67),0))} -> #N/A | J67: =VLOOKUP(D67,FBA地址记录!A:C,3,0) -> 06126 | K67: =IFERROR(VLOOKUP(D67,FBA地址记录!A:B,2,0),"否") -> 否 | L67: 美通 | M67: 欧洲空派A-VAT | P67: =D67&"："&E67&"箱-"&H67&"KG-"&I67&"方" -> #N/A | Q67: =_xlfn.DISPIMG("ID_C70CC3B3F41341FE9648A6B1D8F827F8",1) -> =DISPIMG("ID_C70CC3B3F41341FE9648A6B1D8F827F8",1) | R67: 48 | S67: =R67*H67 -> #N/A | T67: =R67-0.5 -> 47.5 | U67: =T67*H67 -> #N/A | V67: =T67-R67 -> -0.5 | W67: =U67-S67 -> #N/A
A69: 45385 | B69: US | C69: 空运 | D69: MGE1 | E69: {=INDEX($D:$D,MATCH(1,($B:$B=C69)*($C:$C=D69),0))} -> #N/A | F69: {=INDEX($E:$E,MATCH(1,($B:$B=C69)*($C:$C=D69),0))} -> #N/A | G69: {=INDEX($F:$F,MATCH(1,($B:$B=C69)*($C:$C=D69),0))} -> #N/A | H69: =IF(MAX(F69:G69)=0,0,IF(MAX(F69:G69)<21,21,IF(F69>G69,ROUNDUP(F69,0),IFERROR(_xlfn.IFS(B69&C69&L69="US空运速十",ROUNDUP((F69+G69)*0.5,0),B69&C69&L69="US空运原飞航",ROUNDUP((F69+G69)*0.5,0),B69&C69&L69="US空运美通",ROUNDUP((F69+G69)*0.5,0),B69&C69&L69="UK空运美通",ROUNDUP((F69+G69)*0.5,0),B69&C69&L625="DE空运美通",ROUNDUP((F69+G69)*0.5,0)),ROUNDUP(MAX(F69:G69),0))))) -> #N/A | I69: {=INDEX($G:$G,MATCH(1,($B:$B=C69)*($C:$C=D69),0))} -> #N/A | J69: =VLOOKUP(D69,FBA地址记录!A:C,3,0) -> 30517-3002 | K69: =IFERROR(VLOOKUP(D69,FBA地址记录!A:B,2,0),"否") -> 否 | L69: 九方 | M69: 美国空派普货包税(快递派) | P69: =D69&"："&E69&"箱-"&H69&"KG-"&I69&"方" -> #N/A | R69: 50 | S69: =R69*H69 -> #N/A | U69: =T69*H69 -> #N/A | V69: =T69-R69 -> -50 | W69: =U69-S69 -> #N/A
A71: 45397 | B71: CA | C71: 空运 | D71: YYZ7 | E71: {=INDEX($D:$D,MATCH(1,($B:$B=C71)*($C:$C=D71),0))} -> #N/A | F71: {=INDEX($E:$E,MATCH(1,($B:$B=C71)*($C:$C=D71),0))} -> #N/A | G71: {=INDEX($F:$F,MATCH(1,($B:$B=C71)*($C:$C=D71),0))} -> #N/A | H71: =IF(MAX(F71:G71)=0,0,IF(MAX(F71:G71)<21,21,IF(F71>G71,ROUNDUP(F71,0),IFERROR(_xlfn.IFS(B71&C71&L71="US空运速十",ROUNDUP((F71+G71)*0.5,0),B71&C71&L71="US空运原飞航",ROUNDUP((F71+G71)*0.5,0),B71&C71&L71="US空运美通",ROUNDUP((F71+G71)*0.5,0),B71&C71&L71="UK空运美通",ROUNDUP((F71+G71)*0.5,0),B71&C71&L627="DE空运美通",ROUNDUP((F71+G71)*0.5,0)),ROUNDUP(MAX(F71:G71),0))))) -> #N/A | I71: {=INDEX($G:$G,MATCH(1,($B:$B=C71)*($C:$C=D71),0))} -> #N/A | J71: =VLOOKUP(D71,FBA地址记录!A:C,3,0) -> L7E 4L8 | K71: =IFERROR(VLOOKUP(D71,FBA地址记录!A:B,2,0),"否") -> 否 | L71: 美通 | M71: 加拿大空派-C1 | P71: =D71&"："&E71&"箱-"&H71&"KG-"&I71&"方" -> #N/A | R71: 50 | S71: =R71*H71 -> #N/A | U71: =T71*H71 -> #N/A | V71: =T71-R71 -> -50 | W71: =U71-S71 -> #N/A
A72: 45397 | B72: CA | C72: 空运 | D72: YYZ7 | E72: {=INDEX($D:$D,MATCH(1,($B:$B=C72)*($C:$C=D72),0))} -> #N/A | F72: {=INDEX($E:$E,MATCH(1,($B:$B=C72)*($C:$C=D72),0))} -> #N/A | G72: {=INDEX($F:$F,MATCH(1,($B:$B=C72)*($C:$C=D72),0))} -> #N/A | H72: =IF(MAX(F72:G72)=0,0,IF(MAX(F72:G72)<21,21,IF(F72>G72,ROUNDUP(F72,0),IFERROR(_xlfn.IFS(B72&C72&L72="US空运速十",ROUNDUP((F72+G72)*0.5,0),B72&C72&L72="US空运原飞航",ROUNDUP((F72+G72)*0.5,0),B72&C72&L72="US空运美通",ROUNDUP((F72+G72)*0.5,0),B72&C72&L72="UK空运美通",ROUNDUP((F72+G72)*0.5,0),B72&C72&L628="DE空运美通",ROUNDUP((F72+G72)*0.5,0)),ROUNDUP(MAX(F72:G72),0))))) -> #N/A | I72: {=INDEX($G:$G,MATCH(1,($B:$B=C72)*($C:$C=D72),0))} -> #N/A | J72: =VLOOKUP(D72,FBA地址记录!A:C,3,0) -> L7E 4L8 | K72: =IFERROR(VLOOKUP(D72,FBA地址记录!A:B,2,0),"否") -> 否 | L72: 美通 | M72: 加拿大空派普货快线-C1K线 | P72: =D72&"："&E72&"箱-"&H72&"KG-"&I72&"方" -> #N/A | R72: 53 | S72: =R72*H72 -> #N/A | U72: =T72*H72 -> #N/A | V72: =T72-R72 -> -53 | W72: =U72-S72 -> #N/A
A73: 45397 | B73: CA | C73: 空运 | D73: YYZ7 | E73: {=INDEX($D:$D,MATCH(1,($B:$B=C73)*($C:$C=D73),0))} -> #N/A | F73: {=INDEX($E:$E,MATCH(1,($B:$B=C73)*($C:$C=D73),0))} -> #N/A | G73: {=INDEX($F:$F,MATCH(1,($B:$B=C73)*($C:$C=D73),0))} -> #N/A | H73: =IF(MAX(F73:G73)=0,0,IF(MAX(F73:G73)<21,21,IF(F73>G73,ROUNDUP(F73,0),IFERROR(_xlfn.IFS(B73&C73&L73="US空运速十",ROUNDUP((F73+G73)*0.5,0),B73&C73&L73="US空运原飞航",ROUNDUP((F73+G73)*0.5,0),B73&C73&L73="US空运美通",ROUNDUP((F73+G73)*0.5,0),B73&C73&L73="UK空运美通",ROUNDUP((F73+G73)*0.5,0),B73&C73&L629="DE空运美通",ROUNDUP((F73+G73)*0.5,0)),ROUNDUP(MAX(F73:G73),0))))) -> #N/A | I73: {=INDEX($G:$G,MATCH(1,($B:$B=C73)*($C:$C=D73),0))} -> #N/A | J73: =VLOOKUP(D73,FBA地址记录!A:C,3,0) -> L7E 4L8 | K73: =IFERROR(VLOOKUP(D73,FBA地址记录!A:B,2,0),"否") -> 否 | L73: 德速 | M73: 加拿大空派专线(包税) /体积除6000 | P73: =D73&"："&E73&"箱-"&H73&"KG-"&I73&"方" -> #N/A | R73: 54 | S73: =R73*H73 -> #N/A | U73: =T73*H73 -> #N/A | V73: =T73-R73 -> -54 | W73: =U73-S73 -> #N/A
A74: 45397 | B74: CA | C74: 空运 | D74: YYZ7 | E74: {=INDEX($D:$D,MATCH(1,($B:$B=C74)*($C:$C=D74),0))} -> #N/A | F74: {=INDEX($E:$E,MATCH(1,($B:$B=C74)*($C:$C=D74),0))} -> #N/A | G74: {=INDEX($F:$F,MATCH(1,($B:$B=C74)*($C:$C=D74),0))} -> #N/A | H74: =IF(MAX(F74:G74)=0,0,IF(MAX(F74:G74)<21,21,IF(F74>G74,ROUNDUP(F74,0),IFERROR(_xlfn.IFS(B74&C74&L74="US空运速十",ROUNDUP((F74+G74)*0.5,0),B74&C74&L74="US空运原飞航",ROUNDUP((F74+G74)*0.5,0),B74&C74&L74="US空运美通",ROUNDUP((F74+G74)*0.5,0),B74&C74&L74="UK空运美通",ROUNDUP((F74+G74)*0.5,0),B74&C74&L630="DE空运美通",ROUNDUP((F74+G74)*0.5,0)),ROUNDUP(MAX(F74:G74),0))))) -> #N/A | I74: {=INDEX($G:$G,MATCH(1,($B:$B=C74)*($C:$C=D74),0))} -> #N/A | J74: =VLOOKUP(D74,FBA地址记录!A:C,3,0) -> L7E 4L8 | K74: =IFERROR(VLOOKUP(D74,FBA地址记录!A:B,2,0),"否") -> 否 | L74: 九方 | M74: 加拿大空派普货包税 | N74: 加西3区 | P74: =D74&"："&E74&"箱-"&H74&"KG-"&I74&"方" -> #N/A | R74: =46.5+1 -> 47.5 | S74: =R74*H74 -> #N/A | T74: =R74-0.5 -> 47 | U74: =T74*H74 -> #N/A | V74: =T74-R74 -> -0.5 | W74: =U74-S74 -> #N/A
A75: 45397 | B75: CA | C75: 空运 | D75: YYZ7 | E75: {=INDEX($D:$D,MATCH(1,($B:$B=C75)*($C:$C=D75),0))} -> #N/A | F75: {=INDEX($E:$E,MATCH(1,($B:$B=C75)*($C:$C=D75),0))} -> #N/A | G75: {=INDEX($F:$F,MATCH(1,($B:$B=C75)*($C:$C=D75),0))} -> #N/A | H75: =IF(MAX(F75:G75)=0,0,IF(MAX(F75:G75)<21,21,IF(F75>G75,ROUNDUP(F75,0),IFERROR(_xlfn.IFS(B75&C75&L75="US空运速十",ROUNDUP((F75+G75)*0.5,0),B75&C75&L75="US空运原飞航",ROUNDUP((F75+G75)*0.5,0),B75&C75&L75="US空运美通",ROUNDUP((F75+G75)*0.5,0),B75&C75&L75="UK空运美通",ROUNDUP((F75+G75)*0.5,0),B75&C75&L631="DE空运美通",ROUNDUP((F75+G75)*0.5,0)),ROUNDUP(MAX(F75:G75),0))))) -> #N/A | I75: {=INDEX($G:$G,MATCH(1,($B:$B=C75)*($C:$C=D75),0))} -> #N/A | J75: =VLOOKUP(D75,FBA地址记录!A:C,3,0) -> L7E 4L8 | K75: =IFERROR(VLOOKUP(D75,FBA地址记录!A:B,2,0),"否") -> 否 | L75: 原飞航 | M75: 温哥华空派 CA-A-YVR01 | P75: =D75&"："&E75&"箱-"&H75&"KG-"&I75&"方" -> #N/A | R75: 47 | S75: =R75*H75 -> #N/A | U75: =T75*H75 -> #N/A | V75: =T75-R75 -> -47 | W75: =U75-S75 -> #N/A
A77: 45397 | B77: CA | C77: 海运 | D77: YYZ7 | E77: {=INDEX($D:$D,MATCH(1,($B:$B=C77)*($C:$C=D77),0))} -> #N/A | F77: {=INDEX($E:$E,MATCH(1,($B:$B=C77)*($C:$C=D77),0))} -> #N/A | G77: {=INDEX($F:$F,MATCH(1,($B:$B=C77)*($C:$C=D77),0))} -> #N/A | H77: =IF(MAX(F77:G77)=0,0,IF(MAX(F77:G77)<21,21,IF(F77>G77,ROUNDUP(F77,0),IFERROR(_xlfn.IFS(B77&C77&L77="US空运速十",ROUNDUP((F77+G77)*0.5,0),B77&C77&L77="US空运原飞航",ROUNDUP((F77+G77)*0.5,0),B77&C77&L77="US空运美通",ROUNDUP((F77+G77)*0.5,0),B77&C77&L77="UK空运美通",ROUNDUP((F77+G77)*0.5,0),B77&C77&L632="DE空运美通",ROUNDUP((F77+G77)*0.5,0)),ROUNDUP(MAX(F77:G77),0))))) -> #N/A | I77: {=INDEX($G:$G,MATCH(1,($B:$B=C77)*($C:$C=D77),0))} -> #N/A | J77: =VLOOKUP(D77,FBA地址记录!A:C,3,0) -> L7E 4L8 | K77: =IFERROR(VLOOKUP(D77,FBA地址记录!A:B,2,0),"否") -> 否 | L77: 速十 | M77: 加拿大海空联运特快线 | P77: =D77&"："&E77&"箱-"&H77&"KG-"&I77&"方" -> #N/A | R77: 30 | S77: =R77*H77 -> #N/A | T77: 30 | U77: =T77*H77 -> #N/A | V77: =T77-R77 -> 0 | W77: =U77-S77 -> #N/A

Sheet 下拉列表
A1: 站点 | B1: US | C1: 调出仓库 | D1: 水鞋-广州仓 | E1: 调入仓库 | F1: CIKERWEL:US_FBA | G1: 货运方式 | H1: 快递 | I1: 物流方式（名称同物流价卡） | J1: AGL海运 | K1: 物流方式（名称同积加） | L1: AGL物流海运 | M1: 物流商 | N1: 德速
B2: CA | D2: 手套-广州仓 | F2: GLOW:US_FBA | H2: 空运 | J2: AGL空运 | L2: AGL物流空运 | N2: 速十
B3: DE | D3: 眼镜-广州仓 | F3: Mr_y:US_FBA | H3: 海运 | J3: 亚马逊自提 | L3: FBA自提物流 | N3: 美通
B4: UK | D4: 棉帽-广州仓 | F4: RIVMOUNT:US_FBA | H4: 卡航 | J4: 加拿大准时达 包税 | L4: 德速_加拿大海派限时达 | N4: 原飞航
B5: JP | D5: CA仓搜海外仓 | F5: RIVMOUNT:CA_FBA | H5: 亚马逊自提 | J5: 加拿大海速派-美森 | L5: 德速_加拿大海速派-美森 | N5: 九方
D6: DE延讯海外仓 | F6: ROUNDYAP:US_FBA | H6: AGL | J6: 加拿大空派专线(包税) /体积除6000 | L6: 德速_加拿大空派专线(包税) /体积除6000 | N6: 海源
D7: UK延讯海外仓 | F7: SAYOLA:US_FBA | H7: 其他 | J7: 美森限时达-正班 | L7: 德速_美国海卡限时达-美森正班快船-包税 | N7: 东翔
D8: 九方欧洲海外仓 | F8: SAYOLA:CA_FBA | J8: 美国海速派-美森-加班 | L8: 德速_美国海派-美森加班快船 | N8: DHL
D9: 元坤海外仓 | F9: SEEKWAY:US_FBA | J9: 美国海速派-美森-正班 | L9: 德速_美国海派-美森正班快船 | N9: 陈哥快递
D10: 商易德海外仓 | F10: SEEKWAY:CA_FBA | J10: 美国空派普货促销(包税) /体积除6000-快递派 | L10: 德速_美国空派普货促销(包税) /体积除6000-快递派 | N10: AGL
D11: 易速达海外仓 | F11: SEEKWAY:JP_FBA | J11: 美国空派普货快线(包税) /体积除6000-快递派 | L11: 德速_美国空派普货快线(包税) /体积除6000-快递派 | N11: 亚马逊自提
F12: SENWAYZON:US_FBA | J12: 欧空普货不包税EUB | L12: 东翔_欧空快线不包税
F13: SENWAYZON:CA_FBA | J13: 欧洲海运递延-HYD | L13: 东翔_欧洲海派递延
F14: SENWAYZON:EU_FBA | J14: 中欧卡航递延-KCA | L14: 东翔_中欧卡航快线
F15: SENWAYZON:UK_FBA | J15: 中英卡航不包税KCD | L15: 东翔_中英卡航不包税KCD
F16: SIMARI:US_FBA | J16: JC快船海外贴标 | L16: 海源JC快船30%申报
F17: SIMARI:EU_FBA | J17: JP快船海外贴标 | L17: 海源JP快船25%申报
F18: SIMARI:UK_FBA | J18: 东京经济快递 | L18: 海源东京经济快递
F19: SIMARI:JP_FBA | J19: 飞船海转空AGL | L19: 海源飞船海转空AGL
F20: WAYFINDING:US_FBA | J20: 海转空30%包逆算 | L20: 海源海转空FBA35%包逆算
F21: WAYFINDING:CA_FBA | J21: 加拿大空派普货包税（加东1区） | L21: 九方_加拿大空派普货包税（加东1区）
F22: rivbos:US_FBA | J22: 加拿大空派普货包税（加西1区） | L22: 九方_加拿大空派普货包税（加西1区）
F23: rivbos:CA_FBA | J23: 加拿大空派-C1 | L23: 美通加拿大空派-C1
... F32: GLOW:CA_FBA | J32: 中航班车-ZK线 | L32: 美通中航班车-VAT
J33: 中英快车DPD/UPS派 | L33: 美通中英快车DPD/UPS派
J34: 加拿大海空联运YX线 | L34: 速十加拿大海空联运标准线
J35: 加拿大海空联运特快线 | L35: 速十加拿大海空联运特快线
J36: 加拿大海派快线 | L36: 速十加拿大海派快线
J37: 美森船正班船卡派 | L37: 速十美线海卡-美森正班船卡派
J38: 美森限时达 | L38: 速十美线海派-美森限时达
J39: 以星快船海派 | L39: 速十美线海派-以星船海派
J40: 美线促销半泡 | L40: 速十美线空派-促销半泡
J41: 加拿大空派 | L41: 原飞航-华南加拿大空运-温哥华空派
J42: 美国空派大陆-包板 | L42: 原飞航-美国空派-A价/体积除6000
J43: DHL | L43: 快递
J44: U53--美国特快海派 | L44: 美通美森特快
... J65: 美森船加班卡派 | L65: 速十美线海卡-美森加班卡派
J66: 美国空派普货春节特惠(包税) /体积除6000-快递派
J67: 加拿大空派普货包税
J68: 英国空派G线-VAT递延-卡派
...

Sheet 物流渠道信息汇总
A1: 站点 | B1: 货运方式 | C1: 常用说法 | D1: 物流商 | E1: 价卡名称 | F1: 备注 | G1: 价格优惠 | H1: 不同店铺 合并计费 | I1: 积加名称
A2: US | B2: 空运 | C2: 美国空运 | D2: 美通 | E2: 美国空派M1 | F2: 有分泡 | G2: 按价表 | I2: 美通美国空派M1
D3: 美通 | E3: 美国空派M3 | F3: 有分泡 | G3: 按价表 | I3: 美通美国空派M3
D4: 德速 | E4: 美国空派普货促销(包税) /体积除6000-快递派 | G4: 按价表 | I4: 德速_美国空派普货快线(包税) /体积除6000-快递派
D5: 速十 | E5: 美线促销半泡 | G5: 按价表 | I5: 速十美线空派-促销半泡
D6: 九方 | E6: 美国空派普货包税(快递派) | F6: 不足50kg需要提货费35元； 深圳、广州以外的地址会收取提货费用，0.6/KG | H6: 分开制单，合并计费 | I6: 九方_美国空派普货包税(快递派)
D7: 原飞航 | E7: 美国空派专线-包板 | F7: 已不用此渠道；有分泡 | H7: 无法分开主单号，不建议合并 | I7: 原飞航-美国空派专线-包板
E8: 美国空派五日提专线 (快线） | F8: 原飞航渠道名已修改； 有分泡；预计提取3-4工作日 | H8: 无法分开主单号，不建议合并
E9: 美国空派普货专线（ 慢线） | F9: 原飞航渠道名已修改； 有分泡；预计提取7-9工作日 | H9: 无法分开主单号，不建议合并
A10: CA | B10: 空运 | C10: 加拿大空运 | D10: 美通 | E10: 加拿大空派-C1 | F10: 不收纺织品附加费 | G10: 按价表 | H10: 美通CA不能合并计费 | I10: 美通加拿大空派-C1
D11: 美通 | E11: 加拿大空派普货快线-C1K线 | F11: 不收纺织品附加费 | G11: 按价表 | H11: 美通CA不能合并计费
A12: CA | B12: 空运 | D12: 德速 | E12: 加拿大空派专线(包税) /体积除6000 | F12: 空运纺织品附加费+2 | G12: 按价表 | H12: 分开制单，合并计费 | I12: 德速_加拿大空派专线(包税) /体积除6000
A13: CA | B13: 空运 | D13: 九方 | E13: 加拿大空派普货包税 | F13: 分加东区、加西区 纺织品附加费+1， 不足50kg需要提货费35元 深圳、广州以外的地址会收取提货费用，0.6/KG | H13: 分开制单，合并计费 | I13: 九方_加拿大空派普货包税
A14: CA | B14: 空运 | D14: 原飞航 | E14: 华南加拿大空运-温哥华空派 | F14: 不收纺织品附加费 | H14: 无法分开主单号，不建议合并 | I14: 原飞航-华南加拿大空运-温哥华空派
A15: DE | B15: 空运 | C15: 德国空运 (比利时清关） | D15: 美通 | E15: 欧洲空派A-VAT | G15: 按价表 | I15: 美通欧洲空派A-VAT
D16: 美通 | E16: 欧洲空派A线卡派 | F16: 针对德国仓 DTM2、WRO5、HAJ1 | G16: 按价表
D17: 美通 | E17: 欧洲空派AK线-VAT | G17: 按价表 | I17: 美通欧洲空派AK线-VAT
C18: 德国空运 (荷兰清关） | D18: 美通 | E18: 欧洲空派荷兰A线卡派 | F18: 针对德国仓 DTM2、WRO5、HAJ1 | G18: 按价表
D19: 美通 | E19: 欧洲空派荷兰A-VAT | G19: 按价表
A20: UK | B20: 空运 | C20: 英国空运 | D20: 美通 | E20: 英国空派G-VAT递延 | F20: 卡派/DPD派送 | G20: 按价表 | I20: 美通英国空派G-VAT
D21: 美通 | E21: 英国空派G-VAT递延 | F21: 英国仓 BHX4/LBA4，默认卡派派送，会按卡派价格 | G21: 按价表
A22: UK | B22: 空运 | C22: 英国空运 | D22: 美通 | E22: 英国空派GK-VAT递延 | F22: 卡派/DPD派送 | G22: 按价表 | I22: 美通英国空派GK-VAT
A23: US | B23: 海运 | C23: 美国美森正班船 快递派 | D23: 美通 | E23: U53--美国特快海派 | G23: 按价表 | H23: 美通US海运不能合并计费 | I23: 美通美森特快
D24: 德速 | E24: 美国海速派-美森-正班 | G24: 按价表 | H24: 分开制单，合并计费 | I24: 德速_美国海派-美森正班快船
D25: 速十 | E25: 美森正班海派 | G25: 按价表 | H25: 合一张单，分开主单号； 需提前与经理说好 | I25: 速十美线海派-美森限时达
D26: 速十 | E26: 13日限时达 | G26: 按价表 | H26: 合一张单，分开主单号； 需提前与经理说好 | I26: 速十_美国海派渠道（含税）13日限时达
D27: 速十 | E27: 15日限时达 | G27: 按价表 | H27: 合一张单，分开主单号； 需提前与经理说好 | I27: 速十_美国海派渠道（含税）15日限时达
C28: 美国美森正班船 卡派 | D28: 美通 | E28: U5特快专线-U52 | F28: 需考虑集货时效、不足起重需收取附加费 | G28: 按价表 | H28: 美通US海运不能合并计费 | I28: 美通美森特快海卡
D29: 德速 | E29: 美森限时达-正班 | F29: 需考虑集货时效；德速卡派不足起重不收附加费 | G29: 按价表 | H29: 分开制单，合并计费 | I29: 德速_美国海卡限时达-美森正班快船-包税
D30: 速十 | E30: 美森船正班船卡派 | F30: 需考虑集货时效、不足起重需收取附加费 | G30: 按价表 | H30: 合一张单，分开主单号； 需提前与经理说好 | I30: 速十美线海卡-美森正班船卡派
C31: 美国美森加班船 快递派 | D31: 美通 | E31: U63--美国快船海派 | G31: 按价表 | H31: 美通US海运不能合并计费 | I31: 美通-U63-美国快船海派
D32: 德速 | E32: 美国海速派-美森-加班 | G32: 按价表 | H32: 分开制单，合并计费 | I32: 德速_美国海派-美森加班快船
D33: 速十 | E33: 美森加班海派 | G33: 按价表 | H33: 合一张单，分开主单号； 需提前与经理说好 | I33: 速十美线海派-美森加班海派
C34: 美国美森加班船 卡派 | D34: 美通 | E34: U6快线专线-U62 | F34: 需考虑集货时效、不足起重需收取附加费 | G34: 按价表 | H34: 美通US海运不能合并计费 | I34: 美通-U62--美国特快专线--包税
D35: 德速 | E35: 美森准时达-加班 | F35: 需考虑集货时效；德速卡派不足起重不收附加费 | G35: 按价表 | H35: 分开制单，合并计费 | I35: 德速_美国海卡准时达-美森加班快船 包税（kg）
D36: 速十 | E36: 美森船加班卡派 | F36: 需考虑集货时效、不足起重需收取附加费 | G36: 按价表 | H36: 合一张单，分开主单号； 需提前与经理说好 | I36: 速十美线海卡-美森加班卡派
A37: CA | B37: 海运 | C37: 加拿大海运 | D37: 美通 | E37: 加拿大海运UPS派 | F37: UPS派 | G37: 按价表 | H37: 美通CA不能合并计费 | I37: 美通加拿大海派
D38: 德速 | E38: 加拿大准时达 | F38: 卡派 | G38: 按价表 | H38: 分开制单，合并计费 | I38: 德速_加拿大海卡准时达
D39: 德速 | E39: 加拿大限时达（美转加） | F39: 头程是 COSCO，末端卡派 | G39: 按价表 | H39: 分开制单，合并计费
C40: 加拿大海派快线 | D40: 速十 | E40: 加拿大海派快线 | F40: 尾程DHL派送 | G40: 按价表 | H40: 速十CA不能合并计费 | I40: 速十加拿大海派快线
...

Sheet WpsReserved_CellImgList
